Workbook

Sheet Quadrat PtCounts
A1: Date | B1: Location | C1: Data Entry By | D1: # T | E1: Position # on Transect (m) | F1: Acanthophora spicifera | G1: Amansia sp. | H1: Articulated Coralline | I1: Asparagopsis sp | J1: Astronema breviarticulatum | K1: Astronema sp. | L1: Ahnfeltiopsis sp | M1: Avrainvillea lacerata | N1: Bryopsis sp. | O1: Bornatella sphaerica | P1: Caulerpa racemosa | Q1: CCA | R1: Cerramium sp | S1: Chaetomorpha basiretrorsa | T1: Chnoospora sp | U1: Cladophora sp | V1: Codium sp | W1: Codium arabicum | X1: Codium edule | Y1: Codium reediae | Z1: Colpomenia sp. | AA1: Cyanobacteria | AB1: Dasya iridescens | AC1: Dichotomaria marginata | AD1: Dictyosphaeria cavernosa | AE1: Dictyosphaeria versluysii | AF1: Dictyosphaeria sp. | AG1: Dictyota sp | AH1: Dictyota sandvicensis | AI1: Dichtyopterous | AJ1: Gelidiella sp | AK1: Gracilaria sp. | AL1: Gracilaria salicronia | AM1: Halimeda sp | AN1: Ulva | AO1: Hypnea sp. | AP1: Jania pumila | AQ1: Jania sp | AR1: Laurencia sp. | AS1: Laurencia majuscula | AT1: Laurencia mcdermidiae | AU1: Laurencia nidifica | AV1: Liagora sp | AW1: Lobophora sp | AX1: Lobophora obscura | AY1: Lyngbya sp | AZ1: Microdictyon sp. | BA1: Neomeris sp | BB1: Portieria | BC1: Pterocladiella | BD1: Padina sp. | BE1: Sargassum sp. | BF1: Sargassum aquifolium | BG1: Sargassum polyphyllum | BH1: Sphaecelaria sp | BI1: Symploca hypnoides | BJ1: Trichogloea sp | BK1: Turbinaria ornata | BL1: Valonia sp. | BM1: Turf | BN1: Cucumber- Actinopyga | BO1: Hermet crab | BP1: Crab | BQ1: Echinometra | BR1: Snail- Dendropoma | BS1: Urchin | BT1: Cucumber- Holothuria | BU1: Haminoea cymbalum | BV1: Pennaria disticha (christmas tree hydroid) | BW1: Pocillopora damicornis | BX1: Sea Star | BY1: Snail- Littoraria | BZ1: Snail - Nerite | CA1: Snail- Serpulorbis | CB1: Snail- Siphonaria normalis | CC1: sponge | CD1: Sand | CE1: limestone | CF1: Bare Rock | CG1: Rubble | CH1: pebble | CI1: hole | CJ1: Brown Crust | CK1: unknown | CL1: Total Points | CN1: Within 2m proximity of attached coral colony? (Y/N) (Mamala Bay only) | CO1: Sediment Depth
A2: 45305 | B2: ʻEwa | C2: Cassie | D2: 2 | E2: 0 | AO2: 3 | AR2: 3 | BD2: 8 | BM2: 3 | CG2: 11 | CL2: =SUM(F2:CI2) -> 28
A3: 45305 | B3: ʻEwa | C3: Kirby | D3: 3 | E3: 0 | H3: 1 | Q3: 9 | AD3: 2 | AH3: 2 | BD3: 7 | CI3: 1 | CL3: =sum(F3:CI3) -> 22
A4: 45305 | B4: ʻEwa | C4: Blue | D4: 1 | E4: 0 | M4: 6 | AD4: 1 | AR4: 4 | CF4: 14 | CL4: =SUM(F4:CI4) -> 25
A5: 45305 | B5: ʻEwa | C5: Cassie | D5: 2 | E5: 2 | U5: 1 | AL5: 6 | BD5: 10 | BE5: 1 | BM5: 7 | CL5: =SUM(F5:CI5) -> 25
A6: 45305 | B6: ʻEwa | C6: Kirby | D6: 3 | E6: 2 | H6: 2 | AD6: 1 | AH6: 2 | AL6: 6 | BD6: 7 | BM6: 7 | CL6: =sum(F6:CI6) -> 25
A7: 45305 | B7: ʻEwa | C7: Blue | D7: 1 | E7: 2 | M7: 4 | Q7: 3 | AR7: 15 | CD7: 3 | CL7: =SUM(F7:CI7) -> 25
A8: 45305 | B8: ʻEwa | C8: Cassie | D8: 2 | E8: 4 | H8: 2 | M8: 10 | Q8: 5 | U8: 1 | AL8: 1 | BD8: 5 | BM8: 1 | CL8: =SUM(F8:CI8) -> 25
A9: 45305 | B9: ʻEwa | C9: Kirby | D9: 3 | E9: 4 | F9: 1 | Q9: 2 | AD9: 1 | AH9: 4 | AO9: 2 | AZ9: 1 | BD9: 3 | BM9: 10 | CD9: 1 | CL9: =sum(F9:CI9) -> 25
A10: 45305 | B10: ʻEwa | C10: Blue | D10: 1 | E10: 4 | M10: 9 | Q10: 10 | U10: 2 | AR10: 4 | CL10: =SUM(F10:CI10) -> 25
A11: 45305 | B11: ʻEwa | C11: Cassie | D11: 2 | E11: 6 | M11: 2 | U11: 2 | AD11: 1 | AL11: 1 | AO11: 1 | AR11: 1 | BD11: 14 | BM11: 1 | CD11: 2 | CL11: =SUM(F11:CI11) -> 25
A12: 45305 | B12: ʻEwa | C12: Addison | D12: 3 | E12: 6 | F12: 1 | M12: 2 | AR12: 5 | AW12: 1 | AZ12: 6 | BD12: 5 | BK12: 2 | BM12: 1 | CI12: 2 | CL12: =sum(F12:CI12) -> 25
A13: 45305 | B13: ʻEwa | C13: Blue | D13: 1 | E13: 6 | Q13: 3 | AR13: 6 | AW13: 5 | AZ13: 1 | BD13: 6 | BE13: 4 | CL13: =SUM(F13:CI13) -> 25
A14: 45305 | B14: ʻEwa | C14: Cassie | D14: 2 | E14: 8 | M14: 8 | AF14: 3 | AL14: 2 | AO14: 6 | BD14: 5 | BM14: 1 | CL14: =SUM(F14:CI14) -> 25
A15: 45305 | B15: ʻEwa | C15: Addison | D15: 3 | E15: 8 | M15: 3 | Q15: 1 | AH15: 1 | AL15: 1 | AO15: 2 | AZ15: 1 | BD15: 13 | BM15: 3 | CL15: =sum(F15:CI15) -> 25
A16: 45305 | B16: ʻEwa | C16: Blue | D16: 1 | E16: 8 | Q16: 3 | U16: 1 | AL16: 1 | AO16: 5 | BD16: 15 | CL16: =SUM(F16:CI16) -> 25
A17: 45305 | B17: ʻEwa | C17: Hikaru | D17: 2 | E17: 10 | M17: 6 | AC17: 1 | AG17: 1 | AL17: 3 | AO17: 2 | BD17: 6 | BM17: 3 | CD17: 3 | CL17: =SUM(F17:CI17) -> 25
A18: 45305 | B18: ʻEwa | C18: Addison | D18: 3 | E18: 10 | AO18: 5 | BD18: 15 | BM18: 2 | CI18: 3 | CL18: =sum(F18:CI18) -> 25
A19: 45305 | B19: ʻEwa | C19: Josue | D19: 1 | E19: 10 | F19: 1 | G19: 2 | V19: 5 | AL19: 1 | AR19: 3 | BD19: 9 | BM19: 2 | CF19: 1 | CG19: 1 | CL19: =SUM(F19:CI19) -> 25
A20: 45305 | B20: ʻEwa | C20: Hikaru | D20: 2 | E20: 12 | H20: 1 | AF20: 1 | AL20: 1 | AO20: 12 | AR20: 1 | BD20: 1 | CF20: 8 | CL20: =SUM(F20:CI20) -> 25
A21: 45305 | B21: ʻEwa | C21: Biscuit | D21: 3 | E21: 12 | AO21: 2 | AR21: 15 | AZ21: 4 | BD21: 2 | BV21: 1 | CF21: 1 | CL21: =SUM(F21:CI21) -> 25
A22: 45305 | B22: ʻEwa | C22: Josue | D22: 1 | E22: 12 | M22: 4 | Q22: 1 | AR22: 6 | AZ22: 2 | BD22: 11 | BU22: 1 | CL22: =SUM(F22:CI22) -> 25
A23: 45305 | B23: ʻEwa | C23: Hikaru | D23: 2 | E23: 14 | F23: 5 | U23: 1 | AH23: 2 | AW23: 1 | BD23: 13 | CD23: 3 | CL23: =sum(F23:CI23) -> 25
A24: 45305 | B24: ʻEwa | C24: Biscuit | D24: 3 | E24: 14 | F24: 2 | M24: 6 | AO24: 1 | AR24: 7 | AZ24: 3 | BD24: 3 | BJ24: 1 | CF24: 2 | CL24: =SUM(F24:CI24) -> 25
A25: 45305 | B25: ʻEwa | C25: Josue | D25: 1 | E25: 14 | AH25: 5 | AR25: 1 | BD25: 14 | BE25: 2 | CF25: 3 | CL25: =SUM(F25:CI25) -> 25
A26: 45305 | B26: ʻEwa | C26: Hikaru | D26: 2 | E26: 16 | F26: 8 | M26: 7 | BD26: 10 | CL26: =sum(F26:CI26) -> 25
A27: 45305 | B27: ʻEwa | C27: Biscuit | D27: 3 | E27: 16 | F27: 2 | M27: 3 | AF27: 2 | AR27: 11 | AZ27: 6 | BD27: 1 | CL27: =SUM(F27:CI27) -> 25
A28: 45305 | B28: ʻEwa | C28: Josue | D28: 1 | E28: 16 | M28: 4 | AH28: 6 | AQ28: 5 | BD28: 6 | CD28: 1 | CF28: 3 | CL28: =SUM(F28:CI28) -> 25
A29: 45305 | B29: ʻEwa | C29: Hikaru | D29: 2 | E29: 18 | F29: 2 | AD29: 2 | BD29: 10 | CF29: 11 | CL29: =sum(F29:CI29) -> 25
A30: 45305 | B30: ʻEwa | C30: Biscuit | D30: 3 | E30: 18 | M30: 7 | O30: 1 | AD30: 1 | AF30: 1 | AO30: 1 | AQ30: 1 | AR30: 1 | BD30: 2 | CD30: 3 | CF30: 4 | CG30: 3 | CL30: =SUM(F30:CI30) -> 25
A31: 45305 | B31: ʻEwa | C31: Josue | D31: 1 | E31: 18 | M31: 5 | V31: 1 | AH31: 6 | AQ31: 1 | BA31: 2 | BD31: 5 | CD31: 5 | CL31: =SUM(F31:CI31) -> 25
A32: 45305 | B32: ʻEwa | C32: Hikaru | D32: 2 | E32: 20 | BD32: 10 | CD32: 10 | CF32: 5 | CL32: =sum(F32:CI32) -> 25
A33: 45305 | B33: ʻEwa | C33: Biscuit | D33: 3 | E33: 20 | O33: 1 | AF33: 2 | AR33: 1 | BD33: 5 | BM33: 1 | CF33: 11 | CG33: 4 | CL33: =SUM(F33:CI33) -> 25
A34: 45305 | B34: ʻEwa | C34: Josue | D34: 1 | E34: 20 | M34: 5 | AH34: 3 | BD34: 11 | CD34: 5 | CF34: 1 | CL34: =SUM(F34:CI34) -> 25
A35: 45305 | B35: ʻEwa | C35: Hikaru | D35: 2 | E35: 22 | O35: 1 | BD35: 11 | CF35: 13 | CL35: =sum(F35:CI35) -> 25
A36: 45305 | B36: ʻEwa | C36: Biscuit | D36: 3 | E36: 22 | O36: 1 | AF36: 1 | BM36: 5 | CF36: 14 | CG36: 4 | CL36: =SUM(F36:CI36) -> 25
A37: 45305 | B37: ʻEwa | C37: Josue | D37: 1 | E37: 22 | AH37: 1 | AQ37: 1 | AV37: 1 | BD37: 1 | CD37: 5 | CF37: 13 | CG37: 3 | CL37: =SUM(F37:CI37) -> 25
A38: 45318 | B38: Lēʻahi | C38: Hikaru | D38: 4 | E38: 1 | AY38: 1 | BF38: 18 | BK38: 3 | CF38: 3 | CL38: =sum(F38:CI38) -> 25
A39: 45318 | B39: Lēʻahi | C39: Hikaru | D39: 4 | E39: 2 | AR39: 1 | BD39: 4 | BF39: 5 | BG39: 13 | CF39: 2 | CL39: =sum(F39:CI39) -> 25
A40: 45318 | B40: Lēʻahi | C40: Hikaru | D40: 2 | E40: 2 | AH40: 8 | AR40: 1 | AT40: 11 | BF40: 3 | BG40: 1 | CF40: 1 | CL40: =SUM(F40:CI40) -> 25
...

Sheet Summing
A1: Date | B1: classification | C1: Acanthophora spicifera | D1: Amansia sp. | E1: Articulated Coralline | F1: Asparagopsis sp | G1: Astronema breviarticulatum | H1: Astronema sp. | I1: Ahnfeltiopsis sp | J1: Avrainvillea lacerata | K1: Bryopsis sp. | L1: Bornatella sphaerica | M1: Caulerpa racemosa | N1: CCA | O1: Cerramium sp | P1: Chaetomorpha basiretrorsa | Q1: Chnoospora sp | R1: Cladophora sp | S1: Codium sp | T1: Codium arabicum | U1: Codium edule | V1: Codium reediae | W1: Colpomenia sp. | X1: Cyanobacteria | Y1: Dasya iridescens | Z1: Dichotomaria marginata | AA1: Dictyosphaeria cavernosa | AB1: Dictyosphaeria versluysii | AC1: Dictyosphaeria sp. | AD1: Dictyota sp | AE1: Dictyota sandvicensis | AF1: Dichtyopterous | AG1: Gelidiella sp | AH1: Gracilaria sp. | AI1: Gracilaria salicronia | AJ1: Halimeda sp | AK1: Ulva | AL1: Hypnea sp. | AM1: Jania pumila | AN1: Jania sp | AO1: Laurencia sp. | AP1: Laurencia majuscula | AQ1: Laurencia mcdermidiae | AR1: Laurencia nidifica | AS1: Liagora sp | AT1: Lobophora sp | AU1: Lobophora obscura | AV1: Lyngbya sp | AW1: Microdictyon sp. | AX1: Neomeris sp | AY1: Portieria | AZ1: Pterocladiella | BA1: Padina sp. | BB1: Sargassum sp. | BC1: Sargassum aquifolium | BD1: Sargassum polyphyllum | BE1: Sphaecelaria sp | BF1: Symploca hypnoides | BG1: Trichogloea sp | BH1: Turbinaria ornata | BI1: Valonia sp. | BJ1: Turf | BK1: total
A2: 45305 | B2: far shore | C2: 2 | E2: 5 | J2: 33 | N2: 29 | R2: 6 | AA2: 6 | AE2: 8 | AI2: =SUM('Quadrat PtCounts'!AL2:AL13) -> 14 | AL2: =SUM('Quadrat PtCounts'!AO2:AO13) -> 6 | AO2: =SUM('Quadrat PtCounts'!AR2:AR13) -> 38 | AT2: 6 | AW2: 8 | BA2: =SUM('Quadrat PtCounts'!BD2:BD13) -> 65 | BB2: 5 | BH2: 2 | BJ2: =SUM('Quadrat PtCounts'!BM2:BM13) -> 30 | BK2: =SUM(C2:BJ2) -> 263
A3: 45305 | B3: mid shore | C3: 8 | D3: 2 | E3: 1 | J3: =SUM('Quadrat PtCounts'!M14:M24) -> 27 | N3: 5 | R3: 2 | S3: 5 | Z3: 1 | AC3: 4 | AD3: 1 | AE3: 8 | AI3: =SUM('Quadrat PtCounts'!AL14:AL21) -> 9 | AL3: =SUM('Quadrat PtCounts'!AO14:AO24) -> 35 | AO3: =SUM('Quadrat PtCounts'!AR15:AR25) -> 33 | AT3: 1 | AW3: =SUM('Quadrat PtCounts'!AZ14:AZ24) -> 10 | BA3: =SUM('Quadrat PtCounts'!BD14:BD25) -> 107 | BB3: 6 | BG3: 1 | BJ3: 11 | BK3: =SUM(C3:BJ3) -> 277
A4: 45305 | B4: near shore | C4: 12 | J4: =SUM('Quadrat PtCounts'!M26:M35) -> 31 | L4: 4 | S4: 1 | AA4: 3 | AC4: 4 | AE4: =SUM('Quadrat PtCounts'!AH26:AH37) -> 16 | AL4: 1 | AN4: 8 | AO4: =SUM('Quadrat PtCounts'!AR26:AR37) -> 13 | AW4: 6 | AX4: 2 | BA4: =SUM('Quadrat PtCounts'!BD26:BD37) -> 72 | BJ4: 6 | BK4: =SUM(B4:BJ4) -> 179
A5: 45318 | B5: far shore | C5: 2 | L5: 1 | N5: 1 | O5: 1 | AC5: 2 | AE5: 19 | AL5: 2 | AO5: 3 | AP5: 4 | AQ5: =SUM('Quadrat PtCounts'!AT40:AT46) -> 31 | AV5: 5 | AW5: 4 | BA5: =SUM('Quadrat PtCounts'!BD39:BD48) -> 36 | BC5: =SUM('Quadrat PtCounts'!BF38:BF48) -> 58 | BD5: =SUM('Quadrat PtCounts'!BG39:BG48) -> 63 | BE5: 11 | BJ5: 6 | BK5: =SUM(B5:BJ5) -> 249
A6: 45318 | B6: mid shore | L6: =SUM('Quadrat PtCounts'!O51:O65) -> 15 | N6: 8 | AE6: 13 | AJ6: 14 | AL6: 2 | AN6: 19 | AO6: 10 | AP6: 6 | AV6: =SUM('Quadrat PtCounts'!AY49:AY67) -> 46 | AW6: 3 | AX6: 1 | BA6: =SUM('Quadrat PtCounts'!BD49:BD66) -> 167 | BC6: 9 | BD6: =SUM('Quadrat PtCounts'!BG49:BG67) -> 34 | BJ6: =SUM('Quadrat PtCounts'!BM49:BM68) -> 52 | BK6: =SUM(C6:BJ6) -> 399
A7: 45318 | B7: near shore | I7: 2 | O7: 3 | AN7: 8 | AP7: 1 | AV7: 14 | BA7: 11 | BD7: 4 | BJ7: =SUM('Quadrat PtCounts'!BM69:BM80) -> 40 | BK7: =SUM(C7:BJ7) -> 83
