Workbook
Name THEREST: LAMBDA(left, right, self, amount, amount-(left+right))

Sheet Metadata
A1: Date | B1: Location | C1: Team Leader | D1: Team Members | E1: Stressful Events? | F1: Low Tide Time | G1: Low Tide Height | H1: # in field group | I1: # T lines | J1: Longest T (m) | K1: Dist between T pts for Q | L1: # Quad/T | M1: Start time | N1: End time | O1: Weather | P1: Rain events? | Q1: Wave Height | R1: Wind speed | S1: # Visitors | T1: # fishing | U1: # collecting | V1: What collecting? | W1: Notes
A2: 45388 | B2: `Ewa | C2: Addison | D2: Biscut, Blue, Cassie | E2: No | F2: 0.35972222 | G2: -0.16 | H2: 4 | I2: 4 | J2: 20 | K2: 2 | L2: 11 | M2: 0.30555556 | N2: 0.4375 | O2: Partly cloudy | P2: yes | Q2: 1-3 ft | R2: 20mph | S2: 3 | T2: 1 | U2: 0
A3: 45389 | B3: `Ewa | C3: Aadya | D3: Patrick, Nate, Aadya, Ritu | E3: No | F3: 0.38541667 | G3: -0.2 | H3: 5 | I3: 4 | J3: 22 | K3: 2 | L3: 12 | M3: 0.34166667 | N3: 0.39583333 | O3: Cloudy | P3: No | Q3: 7-10ft | R3: 19-24mph | S3: 4 | T3: 2 | U3: 0 | V3: N/A
A4: 45305 | B4: Ewa Beach | C4: Jo | D4: Biscuit, Ritu, Aadya | E4: No | F4: 0.54166667 | G4: 0.1 | H4: 13 | I4: 3 | J4: 24 | K4: 2 | L4: 12 | M4: 0.54583333 | N4: 0.58680556 | O4: Sunny | P4: No | Q4: 1-3 ft | R4: 4-7 mph | S4: 3 | T4: 1 | U4: 2 | V4: Limu
A5: 45332 | B5: Ewa Beach | C5: Josue | D5: Hikaru, Kirby, Josue, Elijah | E5: No | F5: 0.47916667 | G5: -0.19 | H5: 4 | I5: 4 | J5: 22 | K5: 2 | L5: 45576 | M5: 0.45486111 | N5: 0.048611111 | O5: Sunny | P5: No | Q5: 1-3 ft | R5: 7-9 mph | S5: 5 | T5: 0 | U5: 0
A6: 45346 | B6: Kalaeloa | C6: Patrick | D6: Nate, Aadaya, Sophia | E6: No | F6: 0.45486111 | G6: 0.5 | H6: 4 | I6: 4 | J6: 35 | M6: 0.40486111 | N6: 0.49652778 | O6: Cloudy | P6: No | Q6: 5 | R6: 20 | S6: 45422 | T6: 1 | U6: 0
A7: 45353 | B7: Kalaeloa | C7: Nate | D7: Sophia, Nate, Aadya, Ritu | E7: No | F7: 0.051388889 | G7: 0.01 | H7: 4 | I7: 4 | J7: 20 | K7: 2 | L7: 10 | M7: 0.5 | N7: 0.065972222 | O7: Partly cloudy | P7: No | Q7: 1-3 ft | R7: 10-14 mph | S7: 8 | T7: 2 | U7: 0
A8: 45360 | B8: Kalaeloa | C8: Ritu | D8: Sophia, Nate, Aadya, Ritu | E8: No | F8: 0.42847222 | G8: -0.03 | H8: 4 | I8: 4 | J8: 20 | K8: 2 | L8: 10 | M8: 0.38194444 | N8: 0.42152778 | O8: Partly cloudy | P8: Yes | Q8: 1-3ft | R8: 8-12mph | S8: 7 | T8: 3 | U8: 0 | W8: 3 people fishing but using 7 lines
A9: 45332 | B9: Kalealoa | C9: Sophia | D9: Sophia, Nate, Aadya, Ritu | E9: No | F9: 0.48472222 | G9: 0.4 | H9: 5 | I9: 4 | J9: 20 | K9: 2 | L9: 10 | M9: 0.42430556 | N9: 0.51388889 | O9: Partly sunny | P9: Yes | Q9: 4-6 ft | R9: 4-7 mph | S9: 12 | T9: 6 | U9: 0 | W9: Sharp rocks, strong waves
A10: 45318 | B10: Le'ahi | C10: Elijah | D10: Hikaru, Kirby, Josue | E10: Yes | F10: 0.51180556 | G10: 0 | H10: 4 | I10: 4 | J10: 13 | K10: 2 | L10: 45639 | M10: 0.45833333 | N10: 0.045138889 | O10: Cloudy | P10: Yes | Q10: 4.6 ft | R10: 18 kts | S10: 4 | T10: 0 | U10: 2 | V10: Fish
A11: 45333 | B11: Lē'ahi | C11: Kirby | D11: Hikaru, Kirby, Josue, Elijah | E11: No | F11: 0.50069444 | G11: -0.3 | H11: 4 | I11: 4 | J11: 13 | K11: 2 | L11: 45576 | M11: 0.45138889 | N11: 0.51041667 | O11: Sunny | P11: No | Q11: 4 ft | R11: 7-9 mph | S11: 45422 | T11: 0 | U11: 0
A12: 45346 | B12: Lē'ahi | C12: Hikaru | D12: Hikaru, Kirby, Josue, Elijah | E12: No | F12: 0.45486111 | G12: -0.02 | H12: 4 | I12: 4 | J12: 13 | K12: 2 | L12: 10 | M12: 0.42361111 | N12: 0.48958333 | O12: Cloudy | P12: Yes | Q12: 7-10ft | R12: 17mph | S12: 13-20 | T12: 2 | U12: 7 | V12: Geology data
A13: 45347 | B13: Leahi | C13: Josue | D13: Hikaru, Kirby, Josue, Elijah | E13: No | F13: 0.46875 | G13: -0.04 | H13: 4 | I13: 4 | J13: 13 | K13: 2 | L13: 10 | M13: 0.43055556 | N13: 0.49305556 | O13: Partly cloudy | P13: No | Q13: 4-6 ft | R13: 13-18 | S13: 15 | T13: 4
A14: 45332 | B14: Mamala Bay | C14: Addison | D14: Blue, Addison, Buscuit, Cassie | E14: No | F14: 0.47916667 | G14: -0.2 | H14: 4 | I14: 4 | J14: 40 | K14: 5 | L14: 8 | M14: 0.41666667 | N14: 0.52777778 | O14: Sunny | P14: No | Q14: 1-3ft | R14: 14 mph | S14: 1 | T14: 0 | U14: 0
A15: 45346 | B15: Mamala Bay | C15: Cassie | D15: Addison, Biscuit, Blue, Cassie | E15: No | F15: 0.45486111 | H15: 4 | I15: 4 | J15: 40 | K15: 5 | L15: 8 | M15: 0.39930556 | N15: 0.47916667 | O15: Light rain | P15: Yes | Q15: 45294 | R15: 45516 | S15: 0 | T15: 0 | U15: 0
A16: 45347 | B16: Mamala Bay | C16: Blue | D16: Addison, Biscuit, Blue, Cassie | E16: No | F16: 0.4375 | H16: 4 | I16: 4 | J16: 40 | K16: 5 | L16: 8 | M16: 0.38541667 | N16: 0.47916667 | O16: Light rain | P16: Yes | Q16: 45294 | R16: 45389 | S16: 45355 | T16: 2 | U16: 0

Sheet Quadrat PtCounts
BS1: Invertebrates | CI1: Substrate | CQ1: Total
A2: Date | B2: Location | C2: Data Entry By | D2: # T | E2: Position # on Transect (m) | F2: Acanthophora spicifera | G2: Amansia sp. | H2: Articulated Coralline | I2: Asparagopsis sp | J2: Astronema breviarticulatum | K2: Astronema sp. | L2: Ahnfeltiopsis sp | M2: Avrainvillea sp. | N2: Avrainvillea lacerata | O2: Bryopsis sp. | P2: Bornatella sphaerica | Q2: Caulerpa racemosa | R2: CCA | S2: Cerramium sp | T2: cerracia | U2: Chaetomorpha basiretrorsa | V2: Chnoospora sp | W2: Cladophora sp | X2: Codium sp | Y2: Codium arabicum | Z2: Codium edule | AA2: Codium reediae | AB2: Colpomenia sp. | AC2: Colpomenia sinuosa | AD2: Cyanobacteria | AE2: Dasya iridescens | AF2: Dichotomaria marginata | AG2: Dictyosphaeria cavernosa | AH2: Dictyosphaeria versluysii | AI2: Dictyosphaeria sp. | AJ2: Dictyota sp | AK2: Dictyota acutiloba | AL2: Dictyota sandvicensis | AM2: Dichtyopterous | AN2: Gelidiella sp | AO2: Gracilaria sp. | AP2: Gracilaria salicronia | AQ2: Halimeda sp | AR2: Hydroclathrus clathratus | AS2: Ulva | AT2: Hypnea sp. | AU2: Jania pumila | AV2: Jania sp | AW2: Laurencia sp. | AX2: Laurencia majuscula | AY2: Laurencia mcdermidiae | AZ2: Laurencia nidifica | BA2: Liagora sp | BB2: Lobophora sp | BC2: Lobophora obscura | BD2: Lyngbya sp | BE2: Microdictyon sp. | BF2: Neomeris sp | BG2: Portieria | BH2: Pterocladiella | BI2: Padina sp. | BJ2: Sargassum sp. | BK2: Sargassum aquifolium | BL2: Sargassum polyphyllum | BM2: Sphaecelaria sp | BN2: Symploca hypnoides | BO2: Trichogloea sp | BP2: Turbinaria ornata | BQ2: Valonia sp. | BR2: Turf | BS2: Cucumber- Actinopyga | BT2: Hermet crab | BU2: Crab | BV2: Echinometra | BW2: Snail- Dendropoma gregarium | BX2: Urchin | BY2: Cucumber- Holothuria | BZ2: Haminoea cymbalum - green snail | CA2: Pennaria disticha (christmas tree hydroid) | CB2: Pocillopora damicornis | CC2: Sea Star | CD2: Snail- Littoraria | CE2: Snail - Nerite | CF2: Snail- Serpulorbis | CG2: Snail- Siphonaria normalis | CH2: sponge | CI2: Sand | CJ2: limestone | CK2: Bare Rock | CL2: Rubble | CM2: pebble | CN2: hole | CO2: Brown Crust | CP2: unknown | CQ2: Total Points | CS2: Within 2m proximity of attached coral colony? (Y/N) (Mamala Bay only) | CT2: Sediment Depth | CU2: Unknown Bulbous Algae
A3: 45305 | B3: ʻEwa | C3: Cassie | D3: 2 | E3: 0 | AT3: 3 | AW3: 3 | BI3: 8 | CL3: 11 | CQ3: =SUM(F3:CN3) -> 25
A4: 45305 | B4: ʻEwa | C4: Cassie | D4: 2 | E4: 2 | W4: 1 | AP4: 6 | BI4: 10 | BJ4: 1 | BR4: 7 | CQ4: =SUM(F4:CN4) -> 25
A5: 45305 | B5: ʻEwa | C5: Cassie | D5: 2 | E5: 4 | H5: 2 | N5: 10 | R5: 5 | W5: 1 | AP5: 1 | BI5: 5 | BR5: 1 | CQ5: =SUM(F5:CN5) -> 25
A6: 45305 | B6: ʻEwa | C6: Cassie | D6: 2 | E6: 6 | N6: 2 | W6: 2 | AG6: 1 | AP6: 1 | AT6: 1 | AW6: 1 | BI6: 14 | BR6: 1 | CI6: 2 | CQ6: =SUM(F6:CN6) -> 25
A7: 45305 | B7: ʻEwa | C7: Cassie | D7: 2 | E7: 8 | N7: 8 | AI7: 3 | AP7: 2 | AT7: 6 | BI7: 5 | BR7: 1 | CQ7: =SUM(F7:CN7) -> 25
A8: 45305 | B8: ʻEwa | C8: Hikaru | D8: 2 | E8: 10 | N8: 6 | AF8: 1 | AJ8: 1 | AP8: 3 | AT8: 2 | BI8: 6 | BR8: 3 | CI8: 3 | CQ8: =SUM(F8:CN8) -> 25
A9: 45305 | B9: ʻEwa | C9: Hikaru | D9: 2 | E9: 12 | H9: 1 | AI9: 1 | AP9: 1 | AT9: 12 | AW9: 1 | BI9: 1 | CK9: 8 | CQ9: =SUM(F9:CN9) -> 25
A10: 45305 | B10: ʻEwa | C10: Hikaru | D10: 2 | E10: 14 | F10: 5 | W10: 1 | AL10: 2 | BB10: 1 | BI10: 13 | CI10: 3 | CQ10: =sum(F10:CN10) -> 25
A11: 45305 | B11: ʻEwa | C11: Hikaru | D11: 2 | E11: 16 | F11: 8 | N11: 7 | BI11: 10 | CQ11: =sum(F11:CN11) -> 25
A12: 45305 | B12: ʻEwa | C12: Hikaru | D12: 2 | E12: 18 | F12: 2 | AG12: 2 | BI12: 10 | CK12: 11 | CQ12: =sum(F12:CN12) -> 25
A13: 45305 | B13: ʻEwa | C13: Hikaru | D13: 2 | E13: 20 | BI13: 10 | CI13: 10 | CK13: 5 | CQ13: =sum(F13:CN13) -> 25
A14: 45305 | B14: ʻEwa | C14: Hikaru | D14: 2 | E14: 22 | P14: 1 | BI14: 11 | CK14: 13 | CQ14: =sum(F14:CN14) -> 25
A15: 45305 | B15: ʻEwa | C15: Kirby | D15: 3 | E15: 0 | H15: 1 | R15: 9 | AG15: 2 | AL15: 2 | BI15: 7 | BR15: 3 | CN15: 1 | CQ15: =sum(F15:CN15) -> 25
A16: 45305 | B16: ʻEwa | C16: Kirby | D16: 3 | E16: 2 | H16: 2 | AG16: 1 | AL16: 2 | AP16: 6 | BI16: 7 | BR16: 7 | CQ16: =sum(F16:CN16) -> 25
A17: 45305 | B17: ʻEwa | C17: Kirby | D17: 3 | E17: 4 | F17: 1 | R17: 2 | AG17: 1 | AL17: 4 | AT17: 2 | BE17: 1 | BI17: 3 | BR17: 10 | CI17: 1 | CQ17: =sum(F17:CN17) -> 25
A18: 45305 | B18: ʻEwa | C18: Addison | D18: 3 | E18: 6 | F18: 1 | N18: 2 | AW18: 5 | BB18: 1 | BE18: 6 | BI18: 5 | BP18: 2 | BR18: 1 | CN18: 2 | CQ18: =sum(F18:CN18) -> 25
A19: 45305 | B19: ʻEwa | C19: Addison | D19: 3 | E19: 8 | N19: 3 | R19: 1 | AL19: 1 | AP19: 1 | AT19: 2 | BE19: 1 | BI19: 13 | BR19: 3 | CQ19: =sum(F19:CN19) -> 25
A20: 45305 | B20: ʻEwa | C20: Addison | D20: 3 | E20: 10 | AT20: 5 | BI20: 15 | BR20: 2 | CN20: 3 | CQ20: =sum(F20:CN20) -> 25
A21: 45305 | B21: ʻEwa | C21: Biscuit | D21: 3 | E21: 12 | AT21: 2 | AW21: 15 | BE21: 4 | BI21: 2 | CA21: 1 | CK21: 1 | CQ21: =SUM(F21:CN21) -> 25
A22: 45305 | B22: ʻEwa | C22: Biscuit | D22: 3 | E22: 14 | F22: 2 | N22: 6 | AT22: 1 | AW22: 7 | BE22: 3 | BI22: 3 | BO22: 1 | CK22: 2 | CQ22: =SUM(F22:CN22) -> 25
A23: 45305 | B23: ʻEwa | C23: Biscuit | D23: 3 | E23: 16 | F23: 2 | N23: 3 | AI23: 2 | AW23: 11 | BE23: 6 | BI23: 1 | CQ23: =SUM(F23:CN23) -> 25
A24: 45305 | B24: ʻEwa | C24: Biscuit | D24: 3 | E24: 18 | N24: 7 | P24: 1 | AG24: 1 | AI24: 1 | AT24: 1 | AV24: 1 | AW24: 1 | BI24: 2 | CI24: 3 | CK24: 4 | CL24: 3 | CQ24: =SUM(F24:CN24) -> 25
A25: 45305 | B25: ʻEwa | C25: Biscuit | D25: 3 | E25: 20 | P25: 1 | AI25: 2 | AW25: 1 | BI25: 5 | BR25: 1 | CK25: 11 | CL25: 4 | CQ25: =SUM(F25:CN25) -> 25
A26: 45305 | B26: ʻEwa | C26: Biscuit | D26: 3 | E26: 22 | P26: 1 | AI26: 1 | BR26: 5 | CK26: 14 | CL26: 4 | CQ26: =SUM(F26:CN26) -> 25
A27: 45305 | B27: ʻEwa | C27: Josue | D27: 1 | E27: 22 | AL27: 1 | AV27: 1 | BA27: 1 | BI27: 1 | CI27: 5 | CK27: 13 | CL27: 3 | CQ27: =SUM(F27:CN27) -> 25
A28: 45305 | B28: ʻEwa | C28: Josue | D28: 1 | E28: 20 | N28: 5 | AL28: 3 | BI28: 11 | CI28: 5 | CK28: 1 | CQ28: =SUM(F28:CN28) -> 25
A29: 45305 | B29: ʻEwa | C29: Josue | D29: 1 | E29: 18 | N29: 5 | X29: 1 | AL29: 6 | AV29: 1 | BF29: 2 | BI29: 5 | CI29: 5 | CQ29: =SUM(F29:CN29) -> 25
A30: 45305 | B30: ʻEwa | C30: Josue | D30: 1 | E30: 16 | N30: 4 | AL30: 6 | AV30: 5 | BI30: 6 | CI30: 1 | CK30: 3 | CQ30: =SUM(F30:CN30) -> 25
A31: 45305 | B31: ʻEwa | C31: Josue | D31: 1 | E31: 14 | AL31: 5 | AW31: 1 | BI31: 14 | BJ31: 2 | CK31: 3 | CQ31: =SUM(F31:CN31) -> 25
A32: 45305 | B32: ʻEwa | C32: Josue | D32: 1 | E32: 12 | N32: 4 | R32: 1 | AW32: 6 | BE32: 2 | BI32: 11 | BZ32: 1 | CQ32: =SUM(F32:CN32) -> 25
A33: 45305 | B33: ʻEwa | C33: Josue | D33: 1 | E33: 10 | F33: 1 | G33: 2 | X33: 5 | AP33: 1 | AW33: 3 | BI33: 9 | BR33: 2 | CK33: 1 | CL33: 1 | CQ33: =SUM(F33:CN33) -> 25
A34: 45305 | B34: ʻEwa | C34: Blue | D34: 1 | E34: 8 | R34: 3 | W34: 1 | AP34: 1 | AT34: 5 | BI34: 15 | CQ34: =SUM(F34:CN34) -> 25
A35: 45305 | B35: ʻEwa | C35: Blue | D35: 1 | E35: 6 | R35: 3 | AW35: 6 | BB35: 5 | BE35: 1 | BI35: 6 | BJ35: 4 | CQ35: =SUM(F35:CN35) -> 25
A36: 45305 | B36: ʻEwa | C36: Blue | D36: 1 | E36: 4 | N36: 9 | R36: 10 | W36: 2 | AW36: 4 | CQ36: =SUM(F36:CN36) -> 25
A37: 45305 | B37: ʻEwa | C37: Blue | D37: 1 | E37: 2 | N37: 4 | R37: 3 | AW37: 15 | CI37: 3 | CQ37: =SUM(F37:CN37) -> 25
A38: 45305 | B38: ʻEwa | C38: Blue | D38: 1 | E38: 0 | N38: 6 | AG38: 1 | AW38: 4 | CK38: 14 | CQ38: =SUM(F38:CN38) -> 25
A39: 45318 | B39: Leʻahi | C39: Elijah | D39: 3 | E39: 13 | CK39: 25 | CQ39: =SUM(F39:CN39) -> 25
A40: 45318 | B40: Leʻahi | C40: Elijah | D40: 3 | E40: 12 | L40: 2 | BR40: 1 | CM40: 22 | CQ40: =SUM(F40:CN40) -> 25
...

Sheet Quadrat PercentCover
A1: Each transect on each field trip gets ONE line on this sheet (each line should add up to 100 percent) | BX1: Invertebrates | CM1: Substrate | CV1: Total
A2: Date | B2: Location | C2: Data Entry By | D2: # T | E2: Position # on Transect (m) | F2: Acanthophora spicifera | G2: Articulated Coralline | H2: Asteronema sp | I2: Astronema breviarticulatum | J2: Asparagopsis taxiformis | K2: Ahnfeltiopsis sp | L2: Amansia sp. | M2: Avrainvillea sp | N2: Avrainvillea lacerata | O2: Bornatella sphaerica | P2: Botrocladia sp. | Q2: Bryopsis sp. | R2: Caulerpa racemosa | S2: CCA | T2: Cerramium sp | U2: Chaetomorpha basiretrorsa | V2: Chnoospora sp. | W2: Cladophora sp | X2: Cladophora sericea | Y2: Codium sp. | Z2: Codium arabicum | AA2: Codium edule | AB2: Codium reediae | AC2: Colpomenia sp. | AD2: Colpomenia sinuosa | AE2: cyanobacteria | AF2: Dasya iridescens | AG2: Dichotomaria marginata | AH2: Dictyosphaeria sp | AI2: Dictyosphaeria cavernosa | AJ2: Dictyosphaeria versluysii | AK2: Dictyota sp | AL2: Dictyota sandvicensis | AM2: Dichtyopteris sp. | AN2: Gelidiella sp | AO2: Gracillaria sp | AP2: Gracilaria salicornia | AQ2: Halimeda sp. | AR2: Halimeda discoidea | AS2: Hypnea sp. | AT2: Hydroclathrus clathratus | AU2: Jania sp | AV2: Laurencia sp | AW2: Laurencia majuscula | AX2: Laurencia mcdermidiae | AY2: Laurencia nidifica | AZ2: Liagora sp | BA2: Lobophora sp. | BB2: Lobophora obscura | BC2: Lyngbya majuscula | BD2: Marienria sp | BE2: Microdictyon sp | BF2: Neomeris sp. | BG2: Orange crust | BH2: Padina sp | BI2: Pocillopora damicornis | BJ2: Pocillopora meandrina | BK2: Portieria sp | BL2: Pterocladiella capillacea | BM2: Sargassum sp. | BN2: Sargassum aquifolium | BO2: Sargassum polyphyllum | BP2: Sphaecelaria sp | BQ2: Symploca hydnoides | BR2: Trichogloea sp | BS2: Turbinaria ornata | BT2: Turf | BU2: Ulva Lactuca | BV2: Valonia sp. | BX2: Cucumber- Actinopyga | BY2: Urchin - Echinometra mathaei | BZ2: Cucumber- Holothuria | CA2: Haminoea cymbalum - green snail | CB2: nudibranch | CC2: Pennaria disticha (christmas tree hydroid) | CD2: Sea Star | CE2: Snail- Dendropoma | CF2: Snail- Littoraria | CG2: Snail - Nerite | CH2: Snail- Morula uva | CI2: Snail- Serpulorbis | CJ2: Snail- Siphonaria normalis | CK2: Sponge | CL2: Red crab | CM2: Sand | CN2: pebbles | CO2: limestone | CP2: Rubble | CQ2: brown crust | CR2: Bare Rock | CS2: hole | CT2: Coral | CU2: unknon | CV2: Total Points
A3: 45305 | B3: ʻEwa | C3: Cassie | D3: 2 | E3: 0 | S3: 0.08 | AS3: 0.2 | BH3: 0.4 | CP3: 0.32 | CV3: =SUM(F3:CU3) -> 1
A4: 45305 | B4: ʻEwa | C4: Cassie | D4: 2 | E4: 2 | S4: 0.04 | W4: 0.16 | AL4: 0.04 | AP4: 0.16 | BH4: 0.4 | BM4: 0.12 | BT4: 0.08 | CB4: 0.01 | CV4: =SUM(F4:CU4) -> 1.01
A5: 45305 | B5: ʻEwa | C5: Cassie | D5: 2 | E5: 4 | N5: 0.4 | W5: 0.08 | AS5: 0.12 | BH5: 0.16 | BT5: 0.24 | CV5: =SUM(F5:CU5) -> 1
A6: 45305 | B6: ʻEwa | C6: Cassie | D6: 2 | E6: 6 | N6: 0.16 | AH6: 0.08 | AP6: 0.08 | AV6: 0.16 | BH6: 0.4 | BT6: 0.04 | CM6: 0.08 | CV6: =SUM(F6:CU6) -> 1
A7: 45305 | B7: ʻEwa | C7: Cassie | D7: 2 | E7: 8 | AH7: 0.2 | AP7: 0.12 | AS7: 0.28 | BH7: 0.28 | BT7: 0.04 | CM7: 0.08 | CV7: =SUM(F7:CU7) -> 1
A8: 45305 | B8: ʻEwa | C8: Hikaru | D8: 2 | E8: 10 | N8: 0.25 | AG8: 0.01 | AP8: 0.04 | AS8: 0.25 | BH8: 0.25 | CM8: 0.2 | CV8: =SUM(F8:CU8) -> 1
A9: 45305 | B9: ʻEwa | C9: Hikaru | D9: 2 | E9: 12 | G9: 0.01 | AP9: 0.01 | AS9: 0.5 | AV9: 0.01 | BH9: 0.01 | CR9: 0.46 | CV9: =SUM(F9:CU9) -> 1
A10: 44940 | B10: `Ewa (Pu`uloa) | C10: Addison | D10: 3 | E10: 0 | S10: 0.5 | AL10: 0.1 | BH10: 0.3 | BT10: 0.1 | CV10: =SUM(F10:CU10) -> 1
A11: 44940 | B11: `Ewa (Pu`uloa) | C11: Addison | D11: 3 | E11: 2 | AP11: 0.3 | BH11: 0.3 | BT11: 0.4 | CV11: =SUM(F11:CU11) -> 1
A12: 44940 | B12: `Ewa (Pu`uloa) | C12: Addison | D12: 3 | E12: 4 | S12: 0.1 | AS12: 0.15 | AV12: 0.15 | BE12: 0.1 | BH12: 0.2 | BT12: 0.3 | CV12: =SUM(F12:CU12) -> 1
A13: 44940 | B13: `Ewa (Pu`uloa) | C13: Addison | D13: 3 | E13: 6 | N13: 0.2 | S13: 0.1 | AS13: 0.1 | AV13: 0.3 | BH13: 0.2 | BT13: 0.1 | CV13: =SUM(F13:CU13) -> 1
A14: 44940 | B14: `Ewa (Pu`uloa) | C14: Addison | D14: 3 | E14: 8 | N14: 0.1 | AI14: 0.1 | AV14: 0.2 | BH14: 0.5 | BT14: 0.1 | CV14: =SUM(F14:CU14) -> 1
A15: 44940 | B15: `Ewa (Pu`uloa) | C15: Addison | D15: 3 | E15: 10 | AS15: 0.1 | BH15: 0.7 | BT15: 0.1 | CS15: 0.1 | CV15: =SUM(F15:CU15) -> 1
A16: 45305 | B16: ʻEwa | C16: Sophia | D16: 2 | E16: 22 | O16: 0.01 | BH16: 0.5 | CR16: 0.49 | CV16: =SUM(F16:CU16) -> 1
A17: 45305 | B17: ʻEwa | C17: Sophia | D17: 2 | E17: 20 | BH17: 0.38 | CM17: 0.3 | CR17: 0.24 | CV17: =SUM(F17:CU17) -> 0.92
A18: 44940 | B18: ʻEwa | C18: Sophia | D18: 2 | E18: 18 | N18: 0.17 | AI18: 0.03 | BH18: 0.25 | CR18: 0.55 | CV18: =SUM(F18:CU18) -> 1
A19: 44940 | B19: ʻEwa | C19: Sophia | D19: 2 | E19: 16 | F19: 0.19 | N19: 0.14 | W19: 0.07 | BH19: 0.33 | CR19: 0.27 | CV19: =SUM(F19:CU19) -> 1
A20: 44940 | B20: ʻEwa | C20: Sophia | D20: 2 | E20: 14 | F20: 0.13 | AL20: 0.01 | BA20: 0.01 | BH20: 0.52 | CR20: 0.32 | CV20: =SUM(F20:CU20) -> 0.99
A21: 44940 | B21: ʻEwa | C21: Aadya | D21: 3 | E21: 12 | AL21: 0.05 | AS21: 0.1 | AV21: 0.5 | BE21: 0.1 | BH21: 0.1 | CC21: 0.05 | CM21: 0.1 | CV21: =SUM(F21:CU21) -> 1
A22: 44940 | B22: ʻEwa | C22: Aadya | D22: 3 | E22: 14 | F22: 0.05 | AL22: 0.05 | AS22: 0.1 | AV22: 0.2 | BE22: 0.1 | BH22: 0.25 | BM22: 0.05 | BR22: 0.05 | CA22: 0.05 | CM22: 0.1 | CV22: =SUM(F22:CU22) -> 1
A23: 44940 | B23: ʻEwa | C23: Aadya | D23: 3 | E23: 16 | F23: 0.15 | N23: 0.1 | AH23: 0.05 | AV23: 0.3 | BE23: 0.15 | BH23: 0.15 | CM23: 0.1 | CV23: =SUM(F23:CU23) -> 1
A24: 44940 | B24: ʻEwa | C24: Aadya | D24: 3 | E24: 18 | N24: 0.2 | O24: 0.05 | AH24: 0.05 | AV24: 0.1 | BH24: 0.25 | CM24: 0.2 | CP24: 0.15 | CV24: =SUM(F24:CU24) -> 1
A25: 44940 | B25: ʻEwa | C25: Aadya | D25: 3 | E25: 20 | O25: 0.11 | AH25: 0.2 | AV25: 0.01 | BH25: 0.18 | CM25: 0.05 | CR25: 0.45 | CV25: =SUM(F25:CU25) -> 1
A26: 44940 | B26: ʻEwa | C26: Aadya | D26: 3 | E26: 22 | O26: 0.02 | AH26: 0.03 | AU26: 0.03 | AV26: 0.03 | BH26: 0.02 | BT26: 0.33 | CP26: 0.06 | CR26: 0.48 | CV26: =SUM(F26:CU26) -> 1
A27: 44940 | B27: ʻEwa | C27: Josue | D27: 1 | E27: 22 | AZ27: 0.05 | BH27: 0.05 | CM27: 0.4 | CR27: 0.5 | CV27: =SUM(F27:CU27) -> 1
A28: 44940 | B28: ʻEwa | C28: Josue | D28: 1 | E28: 20 | N28: 0.2 | AL28: 0.05 | AV28: 0.05 | BH28: 0.15 | CM28: 0.55 | CV28: =SUM(F28:CU28) -> 1
A29: 44940 | B29: ʻEwa | C29: Josue | D29: 1 | E29: 18 | N29: 0.05 | AL29: 0.25 | AU29: 0.05 | BH29: 0.1 | CM29: 0.55 | CV29: =SUM(F29:CU29) -> 1
A30: 44940 | B30: ʻEwa | C30: Josue | D30: 1 | E30: 16 | AL30: 0.15 | BH30: 0.15 | BM30: 0.15 | CA30: 0.01 | CM30: 0.54 | CV30: =SUM(F30:CU30) -> 1
A31: 44940 | B31: ʻEwa | C31: Josue | D31: 1 | E31: 14 | N31: 0.2 | AL31: 0.1 | AV31: 0.05 | BH31: 0.4 | BM31: 0.05 | CM31: 0.2 | CV31: =SUM(F31:CU31) -> 1
A32: 44940 | B32: ʻEwa | C32: Josue | D32: 1 | E32: 12 | F32: 0.2 | AL32: 0.05 | AP32: 0.05 | AU32: 0.05 | BH32: 0.4 | CR32: 0.25 | CV32: =SUM(F32:CU32) -> 1
A33: 44940 | B33: ʻEwa | C33: Josue | D33: 1 | E33: 10 | Y33: 0.1 | AU33: 0.1 | AV33: 0.05 | BE33: 0.1 | BH33: 0.35 | BM33: 0.1 | CR33: 0.2 | CV33: =SUM(F33:CU33) -> 1
A34: 44940 | B34: ʻEwa | C34: Nate | D34: 1 | E34: 8 | S34: 0.3 | AS34: 0.4 | BH34: 0.3 | CV34: =SUM(F34:CU34) -> 1
A35: 44940 | B35: ʻEwa | C35: Nate | D35: 1 | E35: 6 | S35: 0.1 | AV35: 0.2 | BA35: 0.2 | BH35: 0.3 | BM35: 0.05 | CM35: 0.15 | CV35: =SUM(F35:CU35) -> 1
A36: 44940 | B36: ʻEwa | C36: Nate | D36: 1 | E36: 4 | N36: 0.6 | S36: 0.15 | W36: 0.05 | AV36: 0.3 | CV36: =SUM(F36:CU36) -> 1.1
A37: 44940 | B37: ʻEwa | C37: Nate | D37: 1 | E37: 2 | N37: 0.1 | S37: 0.1 | AV37: 0.7 | CM37: 0.1 | CV37: =SUM(F37:CU37) -> 1
A38: 44940 | B38: ʻEwa | C38: Nate | D38: 1 | E38: 0 | N38: 0.05 | AV38: 0.05 | CR38: 0.9 | CV38: =SUM(F38:CU38) -> 1
A39: 45318 | B39: Leʻahi | C39: Kirby | D39: 1 | E39: 3 | AL39: 0.08 | AX39: 0.3 | BG39: 0.05 | BN39: 0.08 | BO39: 0.1 | CR39: 0.39 | CV39: =SUM(F39:CU39) -> 1
A40: 45318 | B40: Leʻahi | C40: Kirby | D40: 1 | E40: 4 | AX40: 0.1 | BC40: 0.03 | BN40: 0.5 | BO40: 0.05 | CR40: 0.32 | CV40: =SUM(F40:CU40) -> 1
...

Sheet Grouped Quadrat - PtCounts Sum
A1: Each field trip is ONE line on this sheet (combine across all quadrats for point counts) | F1: Algae | AY1: Invertebrates | BK1: Substrate | BP1: Total
A2: Date | B2: Location | C2: Data Entry By | D2: # T | E2: Total #Q | F2: Acanthophora spicifera | G2: Amansia sp. | H2: Articulated Coralline | I2: Asparagopsis sp | J2: Ahnfeltiopsis sp | K2: Avrainvillea lacerata | L2: Bornatella sphaerica | M2: CCA | N2: Cerramium sp | O2: Chaetomorpha basiretrorsa | P2: Chnoospora sp | Q2: Cladophora sp | R2: Codium sp | S2: Codium arabicum | T2: Codium edule | U2: Codium reediae | V2: Colpomenia sp. | W2: Dichotomaria marginata | X2: Dictyosphaeria cavernosa | Y2: Dictyosphaeria sp. | Z2: Dictyota sp | AA2: Dictyota sandvicensis | AB2: Gelidiella sp | AC2: Gracilaria sp. | AD2: Gracilaria salicronia | AE2: Halimeda sp | AF2: Hypnea sp. | AG2: Jania sp | AH2: Laurencia sp. | AI2: Laurencia majuscula | AJ2: Laurencia mcdermidiae | AK2: Laurencia nidifica | AL2: Liagora sp | AM2: Lobophora sp | AN2: Lyngbya sp | AO2: Microdictyon sp. | AP2: Neomeris sp | AQ2: Padina sp. | AR2: Sargassum sp. | AS2: Sargassum aquifolium | AT2: Sargassum polyphyllum | AU2: Sphaecelaria sp | AV2: Trichogloea sp | AW2: Turbinaria ornata | AX2: Turf | AY2: Cucumber- Actinopyga | AZ2: Snail- Dendropoma | BA2: Urchin | BB2: Cucumber- Holothuria | BC2: Haminoea cymbalum | BD2: Pennaria disticha (christmas tree hydroid) | BE2: Sea Star | BF2: Snail- Littoraria | BG2: Snail - Nerite | BH2: Snail- Serpulorbis | BI2: Sponge | BJ2: Snail- Siphonaria normalis | BK2: Sand | BL2: Bare Rock | BM2: Rubble | BN2: pebble | BO2: hole | BP2: Total Points
A3: 45305 | B3: ʻEwa | C3: Joanna | D3: 3 | E3: 36 | F3: 22 | G3: 2 | H3: 6 | I3: 0 | J3: 0 | K3: 91 | L3: 4 | M3: 37 | N3: 0 | Q3: 8 | R3: 6 | S3: 0 | T3: 0 | U3: 0 | W3: 1 | X3: 9 | Y3: 10 | Z3: 1 | AA3: 32 | AB3: 0 | AC3: 0 | AD3: 23 | AE3: 0 | AF3: 42 | AG3: 8 | AH3: 84 | AI3: 0 | AJ3: 0 | AK3: 0 | AL3: 1 | AM3: 7 | AN3: 0 | AO3: 24 | AP3: 2 | AQ3: 244 | AR3: 7 | AS3: 0 | AT3: 0 | AU3: 0 | AV3: 1 | AW3: 2 | AX3: 47 | AY3: 0 | AZ3: 0 | BA3: 0 | BB3: 0 | BC3: 1 | BD3: 1 | BE3: 0 | BF3: 0 | BG3: 0 | BH3: 0 | BI3: 0 | BJ3: 0 | BK3: 41 | BL3: 104 | BM3: 26 | BN3: 0 | BO3: 6 | BP3: 900
A4: 45318 | B4: Leahi | C4: Elijah | D4: 4 | E4: 42 | F4: 2 | G4: 0 | H4: 0 | I4: 0 | J4: 2 | K4: 0 | L4: 16 | M4: 9 | N4: 4 | Q4: 0 | R4: 0 | S4: 0 | T4: 0 | U4: 0 | W4: 0 | X4: 0 | Y4: 0 | Z4: 0 | AA4: 32 | AB4: 0 | AC4: 0 | AD4: 0 | AE4: 14 | AF4: 4 | AG4: 27 | AH4: 13 | AI4: 11 | AJ4: 31 | AK4: 0 | AL4: 0 | AM4: 0 | AN4: 65 | AO4: 7 | AP4: 1 | AQ4: 218 | AR4: 0 | AS4: 67 | AT4: 101 | AU4: 11 | AV4: 0 | AW4: 0 | AX4: 98 | AY4: 0 | AZ4: 6 | BA4: 0 | BB4: 0 | BC4: 0 | BD4: 0 | BE4: 0 | BF4: 0 | BG4: 1 | BH4: 0 | BI4: 0 | BJ4: 1 | BK4: 9 | BL4: 291 | BM4: 0 | BN4: 30 | BO4: 0 | BP4: =SUM(F4:BO4) -> 1071
A5: 45333 | B5: Lēʻahi | C5: Kirby | D5: 4 | E5: 41 | F5: 0 | G5: 0 | H5: 0 | I5: 0 | J5: 0 | K5: 0 | L5: 11 | M5: 22 | N5: 1 | Q5: 0 | R5: 0 | S5: 0 | T5: 0 | U5: 0 | W5: 0 | X5: 0 | Y5: 5 | Z5: 20 | AA5: 23 | AB5: 0 | AC5: 0 | AD5: 0 | AE5: 10 | AF5: 0 | AG5: 44 | AH5: 6 | AI5: 4 | AJ5: 53 | AK5: 0 | AL5: 1 | AM5: 1 | AN5: 37 | AO5: 13 | AP5: 0 | AQ5: 232 | AR5: 0 | AS5: 115 | AT5: 57 | AU5: 0 | AV5: 0 | AW5: 3 | AX5: 18 | AY5: 0 | AZ5: 56 | BA5: 0 | BB5: 0 | BC5: 0 | BD5: 0 | BE5: 0 | BF5: 0 | BG5: 0 | BH5: 0 | BI5: 0 | BJ5: 1 | BK5: 125 | BL5: 134 | BM5: 0 | BN5: 24 | BO5: 0 | BP5: =sum(F5:BO5) -> 1016
A6: 45332 | B6: Ewa | C6: Josue | D6: 4 | E6: 40 | F6: 1 | G6: 1 | K6: =sum('Quadrat PtCounts'!N82:N121) -> 54 | L6: 1 | M6: =SUM('Quadrat PtCounts'!R82:R121) -> 21 | O6: =SUM('Quadrat PtCounts'!U82:U121) -> 15 | P6: 1 | R6: 4 | Y6: =SUM('Quadrat PtCounts'!AI82:AI121) -> 35 | Z6: =SUM('Quadrat PtCounts'!AJ82:AJ121) -> 63 | AA6: =SUM('Quadrat PtCounts'!AL82:AL121) -> 11 | AB6: 2 | AD6: =SUM('Quadrat PtCounts'!AP82:AP121) -> 14 | AF6: =SUM('Quadrat PtCounts'!AT83:AT121) -> 63 | AG6: =SUM('Quadrat PtCounts'!AV82:AV121) -> 10 | AH6: =SUM('Quadrat PtCounts'!AW82:AW121) -> 45 | AI6: =SUM('Quadrat PtCounts'!AX83:AX121) -> 17 | AL6: 9 | AM6: 4 | AO6: =SUM('Quadrat PtCounts'!BE82:BE121) -> 96 | AP6: =SUM('Quadrat PtCounts'!BF82) -> 0 | AQ6: =SUM('Quadrat PtCounts'!BI82:BI121) -> 292 | AT6: 1 | AW6: =SUM('Quadrat PtCounts'!BP82:BP121) -> 25 | AX6: =SUM('Quadrat PtCounts'!BR82:BR121) -> 15 | BD6: 1 | BI6: 3 | BK6: =SUM('Quadrat PtCounts'!CI82:CI121) -> 78 | BL6: =SUM('Quadrat PtCounts'!CK82:CK121) -> 103 | BM6: =SUM('Quadrat PtCounts'!CL82:CL121) -> 0 | BN6: 2 | BO6: 0 | BP6: =SUM(B6:BO6) -> 1031
A7: 45346 | B7: Lēʻahi | C7: Hikaru | D7: 4 | E7: 42 | L7: =sum('Quadrat PtCounts'!P277:P318) -> 1 | M7: =sum('Quadrat PtCounts'!R277:R318) -> 14 | N7: =sum('Quadrat PtCounts'!S277:S318) -> 1 | O7: =sum('Quadrat PtCounts'!U277:U318) -> 2 | V7: =sum('Quadrat PtCounts'!AB277:AB318) -> 1 | Y7: 1 | Z7: =sum('Quadrat PtCounts'!AJ277:AJ318) -> 3 | AA7: =sum('Quadrat PtCounts'!AL277:AL318) -> 19 | AE7: =sum('Quadrat PtCounts'!AQ277:AQ318) -> 6 | AF7: =sum('Quadrat PtCounts'!AT277:AT318) -> 4 | AG7: =sum('Quadrat PtCounts'!AV277:AV318) -> 76 | AH7: =sum('Quadrat PtCounts'!AW277:AW318) -> 9 | AJ7: =sum('Quadrat PtCounts'!AY277:AY318) -> 29 | AN7: =sum('Quadrat PtCounts'!BD277:BD318) -> 32 | AO7: =sum('Quadrat PtCounts'!BE277:BE318) -> 11 | AP7: =sum('Quadrat PtCounts'!BF277:BF318) -> 2 | AQ7: =sum('Quadrat PtCounts'!BI277:BI318) -> 252 | AS7: =sum('Quadrat PtCounts'!BK277:BK318) -> 153 | AT7: =sum('Quadrat PtCounts'!BL277:BL318) -> 18 | AX7: =sum('Quadrat PtCounts'!BR277:BR318) -> 45 | AZ7: =sum('Quadrat PtCounts'!BW277:BW318) -> 26 | BJ7: =sum('Quadrat PtCounts'!CG277:CG318) -> 7 | BK7: =sum('Quadrat PtCounts'!CI277:CI318) -> 128 | BL7: =sum('Quadrat PtCounts'!CK277:CK318) -> 180 | BN7: =sum('Quadrat PtCounts'!CM277:CM318) -> 31 | BP7: =sum(F7:BO7) -> 1051
A8: 45388 | B8: Ewa | C8: Addison | D8: 4 | E8: 48 | F8: 0 | G8: 3 | H8: 0 | I8: 0 | J8: 0 | K8: 0 | L8: 0 | M8: 0 | N8: 52 | O8: 0 | P8: 1 | Q8: 0 | R8: 1 | S8: 0 | T8: 0 | U8: 0 | V8: 0 | W8: 27 | X8: 0 | Y8: 3 | Z8: 2 | AA8: 0 | AB8: 0 | AC8: 1 | AD8: 14 | AE8: 0 | AF8: 0 | AG8: 3 | AH8: 17 | AI8: 0 | AJ8: 0 | AK8: 36 | AL8: 8 | AM8: 0 | AN8: 0 | AO8: 0 | AP8: 9 | AQ8: 0 | AR8: 1 | AS8: 0 | AT8: 26 | AU8: 0 | AV8: 3 | AW8: 2 | AX8: 0 | AY8: 0 | AZ8: 0 | BA8: 0 | BB8: 1 | BC8: 2 | BD8: 0 | BE8: 24 | BF8: 0 | BG8: 0 | BH8: 0 | BI8: 147 | BJ8: 0 | BK8: 0 | BL8: 0 | BM8: 0 | BN8: 1 | BO8: 1 | BP8: 6 | BQ8: 0 | BR8: 50 | BS8: 1 | BT8: 0 | BU8: 0 | BV8: 2 | BW8: 0 | BX8: 0 | BY8: 0 | BZ8: 0 | CA8: 2 | CB8: 0 | CC8: 0 | CD8: 0 | CE8: 0 | CF8: 0 | CG8: 0 | CH8: 0 | CI8: 43 | CJ8: 98 | CK8: 4 | CL8: 7 | CM8: 0 | CN8: 0 | CO8: 0 | CP8: 1 | CQ8: 599

Sheet Grouped Quadrat - PercentCover 
A1: Each field trip is ONE line on this sheet (combine across all quadrats for percent cover) | AY1: Invertebrates | BK1: Substrate
A2: Date | B2: Location | C2: Data Entry By | D2: # T | E2: Total #Q | F2: Acanthophora spicifera | G2: Articulated Coralline | H2: Asparagopsis sp | I2: Asteronema sp | J2: Ahnfeltiopsis sp | K2: Avrainvillea lacerata | L2: Bornatella sphaerica | M2: CCA | N2: Cerramium sp | O2: Chaetomorphabasiretrorsa | P2: Cladophora sp | Q2: Codium sp. | R2: Codium arabicum | S2: Codium edule | T2: Codium reediae | U2: Dichotomaria marginata | V2: Dictyosphaeria sp | W2: Dictyosphaeria cavernosa | X2: Dictyota sp | Y2: Dictyota sandvicensis | Z2: Gelidiella sp | AA2: Gracillaria sp | AB2: Gracilaria salicornia | AC2: Halimeda sp. | AD2: Hypnea sp. | AE2: Jania sp | AF2: Laurencia sp | AG2: Laurencia majuscula | AH2: Laurencia mcdermidiae | AI2: Laurencia nidifica | AJ2: Liagora sp | AK2: Lobophora sp. | AL2: Lyngbya sp. | AM2: Microdictyon sp | AN2: Neomeris sp. | AO2: Padina sp | AP2: Sargassum sp. | AQ2: Sargassum aquifolium | AR2: Sargassum polyphyllum | AS2: Sphaecelaria sp | AT2: Trichogloea sp | AU2: Turbinaria ornata | AV2: Turf | AW2: orange crust | AY2: Cucumber- Actinopyga | AZ2: Urchin | BA2: Cucumber- Holothuria | BB2: Haminoea cymbalum | BC2: nudibranch | BD2: Pennaria disticha (christmas tree hydroid) | BE2: Sea Star | BF2: Snail- Dendropoma | BG2: Snail- Littoraria | BH2: Snail - Nerite | BI2: Snail- Serpulorbis | BJ2: Snail- Siphonaria normalis | BK2: Sand | BL2: pebbles | BM2: Rubble | BN2: Bare Rock | BO2: hole
A3: 45305 | B3: Ewa | C3: Joanna | D3: 3 | E3: 36 | F3: 0.144 | G3: 0.01 | K3: 0.19466667 | L3: 0.0475 | M3: 0.16333333 | P3: 0.09 | Q3: 0.1 | U3: 0.01 | V3: 0.10166667 | W3: 0.065 | Y3: 0.085 | AB3: 0.10857143 | AD3: 0.20909091 | AE3: 0.0575 | AF3: 0.18666667 | AJ3: 0.05 | AK3: 0.105 | AM3: 0.11 | AO3: 0.27969697 | AP3: 0.086666667 | AT3: 0.05 | AV3: 0.16636364 | BB3: 0.03 | BC3: 0.01 | BD3: 0.05 | BK3: 0.23125 | BM3: 0.17666667 | BN3: 0.42583333 | BO3: 0.1
A4: 45318 | B4: Lēʻahi | C4: Elijah | D4: 4 | E4: 42 | F4: 0 | G4: 0 | H4: 0 | J4: 0.02 | K4: 0 | L4: 0.16 | M4: 0.09 | N4: 0.1 | P4: 0 | Q4: 0.02 | R4: 0 | S4: 0 | T4: 0 | U4: 0 | V4: 0 | W4: 0 | X4: 0 | Y4: 0.18 | Z4: 0.02 | AA4: 0 | AB4: 0 | AC4: 0.17 | AD4: 0.1 | AE4: 0.75 | AF4: 0.08 | AG4: 0.05 | AH4: 0.85 | AI4: 0 | AJ4: 0 | AK4: 0.2 | AL4: 1.65 | AM4: 0.05 | AN4: 0.02 | AO4: 8.01 | AP4: 0 | AQ4: 3.21 | AR4: 4.24 | AS4: 0 | AT4: 0 | AU4: 0.1 | AV4: 3.22 | AW4: 0 | AX4: 0 | AY4: 0 | AZ4: 0 | BA4: 0 | BB4: 0 | BC4: 0 | BD4: 0 | BE4: 0 | BF4: 0.25 | BG4: 0.02 | BH4: 0.02 | BI4: 0 | BJ4: 0.07 | BK4: 0.9 | BL4: 1.11 | BM4: 0 | BN4: 15.61 | BO4: 0
A5: 45333 | B5: Lēʻahi | C5: Kirby | D5: 4 | E5: 41 | F5: 0 | G5: 0 | H5: 0 | J5: 0 | K5: 0 | L5: 0.013 | M5: 0.0625 | N5: 0.014 | P5: 0 | Q5: 0 | R5: 0 | S5: 0 | T5: 0 | U5: 0 | V5: 0.024 | W5: 0 | X5: 0.041 | Y5: 0.047 | Z5: 0 | AA5: 0 | AB5: 0.001 | AC5: 0.03 | AD5: 0 | AE5: 0.164 | AF5: 0.058 | AG5: 0 | AH5: 0.208 | AI5: 0 | AJ5: 0 | AK5: 0.03 | AL5: 0.0738 | AM5: 0.0278 | AN5: 0.012 | AO5: 0.362 | AP5: 0 | AQ5: 0.122 | AR5: 0.097 | AS5: 0 | AT5: 0 | AU5: 0 | AV5: 0.125 | AW5: 0 | AY5: 0 | AZ5: 0 | BA5: 0 | BB5: 0 | BC5: 0 | BD5: 0 | BE5: 0 | BF5: 0.383 | BG5: 0 | BH5: 0 | BI5: 0 | BJ5: 0.015 | BK5: 0.397 | BL5: 0.222 | BM5: 0 | BN5: 0.301 | BO5: 0
A6: 45346 | B6: Lēʻahi | C6: Hikaru | D6: 4 | E6: 42 | I6: =sum('Quadrat PercentCover'!H272:H313) -> 0.03 | L6: =sum('Quadrat PercentCover'!O272:O313) -> 0.23 | M6: =sum('Quadrat PercentCover'!S272:S313) -> 0.27 | N6: =sum('Quadrat PercentCover'!T272:T313) -> 0.16 | O6: =sum('Quadrat PercentCover'!U272:U313) -> 0.08 | V6: =sum('Quadrat PercentCover'!AH272:AH313) -> 0.03 | W6: =sum('Quadrat PercentCover'!AI272:AI313) -> 0.02 | X6: =sum('Quadrat PercentCover'!AK272:AK313) -> 0.08 | Y6: =sum('Quadrat PercentCover'!AL272:AL313) -> 0.94 | AC6: =sum('Quadrat PercentCover'!AQ272:AQ313) -> 0.31 | AD6: =sum('Quadrat PercentCover'!AS272:AS313) -> 0.01 | AE6: =sum('Quadrat PercentCover'!AU272:AU313) -> 2.85 | AF6: =sum('Quadrat PercentCover'!AV272:AV313) -> 0.24 | AH6: =sum('Quadrat PercentCover'!AX272:AX313) -> 0.9 | AL6: =sum('Quadrat PercentCover'!BC272:BC313) -> 0.57 | AM6: =sum('Quadrat PercentCover'!BE272:BE313) -> 0.33 | AN6: =sum('Quadrat PercentCover'!BF272:BF313) -> 0.13 | AO6: =sum('Quadrat PercentCover'!BH272:BH313) -> 8.2 | AQ6: =sum('Quadrat PercentCover'!BN272:BN313) -> 4.81 | AR6: =sum('Quadrat PercentCover'!BO272:BO313) -> 0.79 | AU6: =sum('Quadrat PercentCover'!BS272:BS313) -> 0.01 | AV6: =sum('Quadrat PercentCover'!BT272:BT313) -> 1.99 | BF6: =sum('Quadrat PercentCover'!CE272:CE313) -> 0.81 | BJ6: =sum('Quadrat PercentCover'!CJ272:CJ313) -> 0.18 | BK6: =sum('Quadrat PercentCover'!CM272:CM313) -> 7.25 | BL6: =sum('Quadrat PercentCover'!CN272:CN313) -> 1.47 | BN6: =sum('Quadrat PercentCover'!CR272:CR313) -> 9.31
A7: 45388 | B7: `Ewa | C7: Addison | D7: 4 | E7: 48 | F7: 0.013888889 | G7: 0.03125 | L7: 0.041666667 | N7: 0.19117037 | O7: 0.007 | S7: 0.017888889 | W7: 0.12013889 | Z7: 0.027777778 | AA7: 0.032407407 | AD7: 0.015 | AE7: 0.18272222 | AI7: 0.032222222 | AJ7: 0.024611111 | AK7: 0.027777778 | AL7: 0.02770202 | AP7: 0.027962963 | AS7: 0.21161111 | AT7: 0.002 | AU7: 0.048611111 | AZ7: 0.0075 | BA7: 0.0096296296 | BE7: 0.15781111 | BF7: 0.001 | BH7: 0.28230918 | BP7: 0.0056666667 | BQ7: 0.013888889 | BR7: 0.0094444444 | BS7: 0.018611111 | BT7: 0.12195556 | BY7: 0.0089814815 | CA7: 0.0037272727 | CB7: 0.01 | CC7: 0.013888889 | CE7: 0.005 | CK7: 0.01 | CM7: 0.11508547 | CO7: 0.24809804 | CP7: 0.086805556 | CR7: 0.027777778 | CU7: 0.031111111

Sheet Sediment Data
A1: Date | B1: Site | C1: Transect # | D1: Quadrat point # | E1: Distance from shore (m) | F1: Sediment Depth (mm) | G1: %Non-Invasive Algae Cover | I1: Acanthophora spicifera | J1: Articulated Coralline | K1: Asteronema sp | L1: Astronema breviarticulatum | M1: Asparagopsis sp | N1: Ahnfeltiopsis sp | O1: Amansia sp. | P1: Avrainvillea lacerata | Q1: Bornatella sphaerica | R1: Botrocladia sp. | S1: Bryopsis sp. | T1: Caulerpa racemosa | U1: CCA | V1: Cerramium sp | W1: Chaetomorpha basiretrorsa | X1: Chnoospora sp. | Y1: Cladophora sp | Z1: Codium sp. | AA1: Codium arabicum | AB1: Codium edule | AC1: Codium reediae | AD1: Colpomenia sp. | AE1: cyanobacteria | AF1: Dasya iridescens | AG1: Dichotomaria marginata | AH1: Dictyosphaeria sp | AI1: Dictyosphaeria cavernosa | AJ1: Dictyosphaeria versluysii | AK1: Dictyota sp | AL1: Dictyota sandvicensis | AM1: Dichtyopterous | AN1: Gelidiella sp | AO1: Gracillaria sp | AP1: Gracilaria salicornia | AQ1: Halimeda sp. | AR1: Halimeda discoidea | AS1: Hypnea sp. | AU1: Jania sp | AV1: Laurencia sp | AW1: Laurencia majuscula | AX1: Laurencia mcdermidiae | AY1: Laurencia nidifica | AZ1: Liagora sp | BA1: Lobophora sp. | BB1: Lyngbya sp. | BC1: Marienria | BD1: Microdictyon sp | BE1: Neomeris sp. | BF1: Orange crust | BG1: Padina sp | BH1: Pocillopora damicornis | BI1: Pocillopora meandrina | BJ1: Portieria | BK1: Pterocladiella capillacea | BL1: Sargassum sp. | BM1: Sargassum aquifolium | BN1: Sargassum polyphyllum | BO1: Sphaecelaria sp | BP1: Symploca hypnoides | BQ1: Trichogloea sp | BR1: Turbinaria ornata | BS1: Turf | BT1: Ulva Lactuca | BU1: Valonia sp. | BW1: Cucumber- Actinopyga | BX1: Urchin - Echinometra mathaei | BY1: Cucumber- Holothuria | BZ1: Haminoea cymbalum | CA1: nudibranch | CB1: Pennaria disticha (christmas tree hydroid) | CC1: Sea Star | CD1: Snail- Dendropoma | CE1: Snail- Littoraria | CF1: Snail - Nerite | CG1: Snail- Serpulorbis | CH1: Snail- Siphonaria normalis | CI1: Sponge | CJ1: Red crab | CK1: Sand | CL1: pebbles | CM1: limestone | CN1: Rubble | CO1: brown crust | CP1: Bare Rock | CQ1: hole | CR1: Coral
A2: 45332 | B2: Mamala | C2: 1 | D2: 40 | E2: 0 | F2: 0 | G2: =sum(I2:BU2)-(I2+P2+AE2+AO2+AP2+AS2+AU2+BB2+BS2) -> 0.55 | K2: 0.05 | U2: 0.1 | AP2: 0.05 | BG2: 0.4 | BS2: 0.4 | CS2: =sum(I2:CQ2) -> 1
A3: 45332 | B3: Mamala | C3: 1 | D3: 35 | E3: 5 | F3: 1 | G3: =sum(I3:BU3)-(I3+P3+AE3+AO3+AP3+AS3+AU3+BB3+BS3) -> 0.4 | U3: 0.1 | BA3: 0.05 | BG3: 0.25 | BS3: 0.5 | CK3: 0.1 | CS3: =sum(I3:CQ3) -> 1
A4: 45332 | B4: Mamala | C4: 1 | D4: 30 | E4: 10 | F4: 0 | G4: =sum(I4:BU4)-(I4+P4+AE4+AO4+AP4+AS4+AU4+BB4+BS4) -> 0.65 | K4: 0.1 | U4: 0.3 | BG4: 0.25 | BS4: 0.35 | CS4: =sum(I4:CQ4) -> 1
A5: 45332 | B5: Mamala | C5: 1 | D5: 25 | E5: 15 | F5: 1 | G5: =sum(I5:BU5)-(I5+P5+AE5+AO5+AP5+AS5+AU5+BB5+BS5) -> 0.5 | U5: 0.15 | BG5: 0.35 | CK5: 0.1 | CO5: 0.2 | CP5: 0.2 | CS5: =sum(I5:CQ5) -> 1
A6: 45332 | B6: Mamala | C6: 1 | D6: 20 | E6: 20 | F6: 1 | G6: =sum(I6:BU6)-(I6+P6+AE6+AO6+AP6+AS6+AU6+BB6+BS6) -> 0.2 | U6: 0.05 | BG6: 0.15 | BS6: 0.3 | CP6: 0.5 | CS6: =sum(I6:CQ6) -> 1
A7: 45332 | B7: Mamala | C7: 1 | D7: 15 | E7: 25 | F7: 0 | G7: =sum(I7:BU7)-(I7+P7+AE7+AO7+AP7+AS7+AU7+BB7+BS7) -> 0.15 | K7: 0.05 | AP7: 0.05 | BG7: 0.1 | BS7: 0.75 | CK7: 0.05 | CS7: =sum(I7:CQ7) -> 1
A8: 45332 | B8: Mamala | C8: 1 | D8: 10 | E8: 30 | F8: 5 | G8: =sum(I8:BU8)-(I8+P8+AE8+AO8+AP8+AS8+AU8+BB8+BS8) -> 0.1 | K8: 0.05 | U8: 0.05 | BX8: 0.05 | CK8: 0.75 | CM8: 0.1 | CS8: =sum(I8:CQ8) -> 1
A9: 45332 | B9: Mamala | C9: 1 | D9: 5 | E9: 35 | F9: 5 | G9: =sum(I9:BU9)-(I9+P9+AE9+AO9+AP9+AS9+AU9+BB9+BS9) -> 0.15 | K9: 0.1 | U9: 0.05 | AS9: 0.05 | CK9: 0.7 | CN9: 0.1 | CS9: =sum(I9:CQ9) -> 1
A10: 45332 | B10: Mamala | C10: 1 | D10: 0 | E10: 40 | F10: 1 | G10: =sum(I10:BU10)-(I10+P10+AE10+AO10+AP10+AS10+AU10+BB10+BS10) -> 0 | CK10: 1 | CS10: =sum(I10:CQ10) -> 1
A11: 45332 | B11: Mamala | C11: 2 | E11: 0 | G11: =sum(I11:BU11)-(I11+P11+AE11+AO11+AP11+AS11+AU11+BB11+BS11) -> 0.67166667 | J11: =5/36 -> 0.13888889 | P11: 0.005 | Q11: =4/36 -> 0.11111111 | U11: =9/36 -> 0.25 | AF11: 0.005 | AU11: =6/36 -> 0.16666667 | BA11: =1/36 -> 0.027777778 | BG11: =5/36 -> 0.13888889 | CN11: =1/36 -> 0.027777778 | CP11: =5/36 -> 0.13888889 | CS11: =sum(I11:CQ11) -> 1.01
A12: 45332 | B12: Mamala | C12: 2 | E12: 5 | G12: =sum(I12:BU12)-(I12+P12+AE12+AO12+AP12+AS12+AU12+BB12+BS12) -> 0.59333333 | Q12: 0.005 | U12: =3/36 -> 0.083333333 | AB12: =4/36 -> 0.11111111 | AS12: =11/36 -> 0.30555556 | AU12: =2/36 -> 0.055555556 | BA12: 0.005 | BB12: 0.005 | BG12: =14/36 -> 0.38888889 | CN12: =2/36 -> 0.055555556 | CP12: 0.005 | CS12: =sum(I12:CQ12) -> 1.02
A13: 45332 | B13: Mamala | C13: 2 | E13: 10 | G13: =sum(I13:BU13)-(I13+P13+AE13+AO13+AP13+AS13+AU13+BB13+BS13) -> 0.67166667 | U13: =1/36 -> 0.027777778 | AS13: =1/36 -> 0.027777778 | AU13: =6/36 -> 0.16666667 | AV13: 0.005 | BA13: =7/36 -> 0.19444444 | BG13: =16/36 -> 0.44444444 | BS13: =1/36 -> 0.027777778 | CN13: =4/36 -> 0.11111111 | CS13: =sum(I13:CQ13) -> 1.005
A14: 45332 | B14: Mamala | C14: 2 | E14: 15 | G14: =sum(I14:BU14)-(I14+P14+AE14+AO14+AP14+AS14+AU14+BB14+BS14) -> 0.42166667 | J14: 0.005 | U14: =2/36 -> 0.055555556 | AB14: =2/36 -> 0.055555556 | AU14: =7/36 -> 0.19444444 | BA14: =3/36 -> 0.083333333 | BG14: =8/36 -> 0.22222222 | CK14: =4/36 -> 0.11111111 | CN14: =10/36 -> 0.27777778 | CS14: =sum(I14:CQ14) -> 1.005
A15: 45332 | B15: Mamala | C15: 2 | E15: 20 | G15: =sum(I15:BU15)-(I15+P15+AE15+AO15+AP15+AS15+AU15+BB15+BS15) -> 0.755 | P15: 0.005 | U15: =3/36 -> 0.083333333 | AF15: 0.005 | AU15: 0.005 | BA15: =4/36 -> 0.11111111 | BG15: =20/36 -> 0.55555556 | BS15: =3/36 -> 0.083333333 | CN15: =6/36 -> 0.16666667 | CS15: =sum(I15:CQ15) -> 1.015
A16: 45332 | B16: Mamala | C16: 2 | E16: 25 | G16: =sum(I16:BU16)-(I16+P16+AE16+AO16+AP16+AS16+AU16+BB16+BS16) -> 0.755 | K16: 0.005 | U16: =1/36 -> 0.027777778 | AU16: =7/36 -> 0.19444444 | BA16: =7/36 -> 0.19444444 | BG16: =19/36 -> 0.52777778 | BS16: =2/36 -> 0.055555556 | CK16: 0.005 | CN16: 0.005 | CS16: =sum(I16:CQ16) -> 1.015
A17: 45332 | B17: Mamala | C17: 2 | E17: 30 | G17: =sum(I17:BU17)-(I17+P17+AE17+AO17+AP17+AS17+AU17+BB17+BS17) -> 0.18166667 | K17: =1/36 -> 0.027777778 | U17: =1/36 -> 0.027777778 | AA17: =2/36 -> 0.055555556 | AJ17: 0.005 | AU17: =12/36 -> 0.33333333 | BA17: =1/36 -> 0.027777778 | BD17: 0.005 | BE17: 0.005 | BG17: =1/36 -> 0.027777778 | BS17: =6/36 -> 0.16666667 | CP17: =12/36 -> 0.33333333 | CS17: =sum(I17:CQ17) -> 1.015
A18: 45332 | B18: Mamala | C18: 2 | E18: 35 | G18: =sum(I18:BU18)-(I18+P18+AE18+AO18+AP18+AS18+AU18+BB18+BS18) -> 0.11611111 | I18: 0.005 | K18: =1/36 -> 0.027777778 | U18: 0.005 | AS18: =12/36 -> 0.33333333 | AU18: =10/36 -> 0.27777778 | BA18: =1/36 -> 0.027777778 | BG18: =2/36 -> 0.055555556 | CK18: =10/36 -> 0.27777778 | CP18: 0.005 | CS18: =sum(I18:CQ18) -> 1.015
A19: 45332 | B19: Mamala | C19: 2 | E19: 40 | G19: =sum(I19:BU19)-(I19+P19+AE19+AO19+AP19+AS19+AU19+BB19+BS19) -> 0.060555556 | AU19: =5/36 -> 0.13888889 | AV19: =2/36 -> 0.055555556 | BE19: 0.005 | BS19: =1/36 -> 0.027777778 | CK19: =24/36 -> 0.66666667 | CN19: =3/36 -> 0.083333333 | CP19: =1/36 -> 0.027777778 | CS19: =sum(I19:CQ19) -> 1.005
A20: 45332 | B20: Mamala | C20: 3 | E20: 0 | G20: =sum(I20:BU20)-(I20+P20+AE20+AO20+AP20+AS20+AU20+BB20+BS20) -> 0.7 | K20: 0.25 | U20: 0.45 | AP20: 0.1 | BS20: 0.2 | CS20: =sum(I20:CQ20) -> 1
A21: 45332 | B21: Mamala | C21: 3 | E21: 5 | G21: =sum(I21:BU21)-(I21+P21+AE21+AO21+AP21+AS21+AU21+BB21+BS21) -> 0.55 | K21: 0.4 | U21: 0.15 | AP21: 0.05 | BS21: 0.15 | CK21: 0.15 | CN21: 0.1 | CS21: =sum(I21:CQ21) -> 1
A22: 45332 | B22: Mamala | C22: 3 | E22: 10 | G22: =sum(I22:BU22)-(I22+P22+AE22+AO22+AP22+AS22+AU22+BB22+BS22) -> 0.4 | K22: 0.4 | BS22: 0.3 | CK22: 0.1 | CM22: 0.2 | CS22: =sum(I22:CQ22) -> 1
A23: 45332 | B23: Mamala | C23: 3 | E23: 15 | G23: =sum(I23:BU23)-(I23+P23+AE23+AO23+AP23+AS23+AU23+BB23+BS23) -> 0.5 | I23: 0.1 | K23: 0.4 | AP23: 0.05 | BG23: 0.1 | BS23: 0.2 | CK23: 0.05 | CM23: 0.1 | CS23: =sum(I23:CQ23) -> 1
A24: 45332 | B24: Mamala | C24: 3 | E24: 20 | G24: =sum(I24:BU24)-(I24+P24+AE24+AO24+AP24+AS24+AU24+BB24+BS24) -> 0.45 | K24: 0.4 | AP24: 0.1 | BG24: 0.05 | BS24: 0.35 | CM24: 0.1 | CS24: =sum(I24:CQ24) -> 1
A25: 45332 | B25: Mamala | C25: 3 | E25: 25 | G25: =sum(I25:BU25)-(I25+P25+AE25+AO25+AP25+AS25+AU25+BB25+BS25) -> 0.35 | K25: 0.2 | U25: 0.15 | BS25: 0.3 | CK25: 0.2 | CN25: 0.15 | CS25: =sum(I25:CQ25) -> 1
A26: 45332 | B26: Mamala | C26: 3 | E26: 30 | G26: =sum(I26:BU26)-(I26+P26+AE26+AO26+AP26+AS26+AU26+BB26+BS26) -> 0.35 | K26: 0.2 | U26: 0.05 | AS26: 0.15 | AZ26: 0.1 | BS26: 0.2 | CK26: 0.2 | CN26: 0.1 | CS26: =sum(I26:CQ26) -> 1
A27: 45332 | B27: Mamala | C27: 3 | E27: 35 | G27: =sum(I27:BU27)-(I27+P27+AE27+AO27+AP27+AS27+AU27+BB27+BS27) -> 0.65 | I27: 0.05 | K27: 0.1 | U27: 0.2 | AK27: 0.25 | AS27: 0.3 | BA27: 0.1 | CS27: =sum(I27:CQ27) -> 1
A28: 45332 | B28: Mamala | C28: 3 | E28: 40 | G28: =sum(I28:BU28)-(I28+P28+AE28+AO28+AP28+AS28+AU28+BB28+BS28) -> 0.25 | J28: 0.1 | K28: 0.1 | BG28: 0.05 | CN28: 0.45 | CP28: 0.3 | CS28: =sum(I28:CQ28) -> 1
A29: 45346 | B29: Mamala Bay | C29: 4 | E29: 0 | G29: =sum(I29:BU29)-(I29+P29+AE29+AO29+AP29+AS29+AU29+BB29+BS29) -> 0.33333333 | K29: =5/36 -> 0.13888889 | U29: =4/36 -> 0.11111111 | AB29: =1/36 -> 0.027777778 | AU29: =13/36 -> 0.36111111 | BA29: =2/36 -> 0.055555556 | CK29: =1/36 -> 0.027777778 | CN29: =5/36 -> 0.13888889 | CP29: =5/36 -> 0.13888889 | CS29: =sum(I29:CQ29) -> 1
A30: 45346 | B30: Mamala Bay | C30: 4 | E30: 5 | G30: =sum(I30:BU30)-(I30+P30+AE30+AO30+AP30+AS30+AU30+BB30+BS30) -> 0.58833333 | K30: =18/36 -> 0.5 | Q30: =1/36 -> 0.027777778 | AU30: =2/36 -> 0.055555556 | BA30: 0.005 | BB30: =1/36 -> 0.027777778 | BG30: =2/36 -> 0.055555556 | BW30: =4/36 -> 0.11111111 | BX30: 0.005 | CK30: =8/36 -> 0.22222222 | CN30: 0.005 | CP30: 0.005 | CS30: =sum(I30:CQ30) -> 1.02
A31: 45346 | B31: Mamala Bay | C31: 4 | E31: 10 | G31: =sum(I31:BU31)-(I31+P31+AE31+AO31+AP31+AS31+AU31+BB31+BS31) -> 0.17166667 | I31: =1/36 -> 0.027777778 | K31: =6/36 -> 0.16666667 | AU31: =3/36 -> 0.083333333 | BA31: 0.005 | CK31: =23/36 -> 0.63888889 | CN31: =2/36 -> 0.055555556 | CP31: =1/36 -> 0.027777778 | CS31: =sum(I31:CQ31) -> 1.005
A32: 45346 | B32: Mamala Bay | C32: 4 | E32: 15 | G32: =sum(I32:BU32)-(I32+P32+AE32+AO32+AP32+AS32+AU32+BB32+BS32) -> 0.27 | J32: =4/36 -> 0.11111111 | K32: =5/36 -> 0.13888889 | AR32: 0.005 | AV32: 0.005 | BP32: 0.005 | BQ32: 0.005 | BS32: 0.005 | CK32: =25/36 -> 0.69444444 | CN32: =2/36 -> 0.055555556 | CS32: =sum(I32:CQ32) -> 1.025
A33: 45346 | B33: Mamala Bay | C33: 4 | E33: 20 | G33: =sum(I33:BU33)-(I33+P33+AE33+AO33+AP33+AS33+AU33+BB33+BS33) -> 0.20444444 | J33: =3/36 -> 0.083333333 | K33: =3/36 -> 0.083333333 | AR33: 0.005 | AS33: 0.005 | AU33: =5/36 -> 0.13888889 | AV33: =1/36 -> 0.027777778 | BE33: 0.005 | BW33: 0.03 | CK33: =20/36 -> 0.55555556 | CN33: =4/36 -> 0.11111111 | CS33: =sum(I33:CQ33) -> 1.045
A34: 45346 | B34: Mamala Bay | C34: 4 | E34: 25 | G34: =sum(I34:BU34)-(I34+P34+AE34+AO34+AP34+AS34+AU34+BB34+BS34) -> 0.39888889 | J34: =2/36 -> 0.055555556 | K34: =7/36 -> 0.19444444 | Q34: 0.005 | AB34: =2/36 -> 0.055555556 | AU34: =6/36 -> 0.16666667 | BA34: =3/36 -> 0.083333333 | BE34: 0.005 | CJ34: 0.005 | CK34: =1/36 -> 0.027777778 | CN34: =15/36 -> 0.41666667 | CP34: 0.005 | CS34: =sum(I34:CQ34) -> 1.02
A35: 45346 | B35: Mamala Bay | C35: 4 | E35: 30 | G35: =sum(I35:BU35)-(I35+P35+AE35+AO35+AP35+AS35+AU35+BB35+BS35) -> 0.53 | K35: =9/36 -> 0.25 | Q35: 0.005 | T35: 0.01 | U35: 0.005 | AB35: 0.005 | AS35: 0.005 | AU35: =16/36 -> 0.44444444 | BE35: 0.005 | BG35: =9/36 -> 0.25 | BS35: =1/36 -> 0.027777778 | CK35: 0.3 | CN35: =1/36 -> 0.027777778 | CS35: =sum(I35:CQ35) -> 1.335
A36: 45346 | B36: Mamala Bay | C36: 4 | E36: 35 | G36: =sum(I36:BU36)-(I36+P36+AE36+AO36+AP36+AS36+AU36+BB36+BS36) -> 0.55 | K36: 0.3 | U36: 0.05 | BA36: 0.1 | BG36: 0.1 | BS36: 0.15 | CK36: 0.15 | CQ36: 0.15 | CS36: =sum(I36:CQ36) -> 1
A37: 45346 | B37: Mamala Bay | C37: 4 | E37: 40 | G37: =sum(I37:BU37)-(I37+P37+AE37+AO37+AP37+AS37+AU37+BB37+BS37) -> 0.4 | J37: 0.05 | K37: 0.15 | U37: 0.15 | AS37: 0.2 | BA37: 0.05 | BS37: 0.05 | CK37: 0.3 | CN37: 0.05 | CS37: =sum(I37:CQ37) -> 1
A38: 45360 | B38: Barber's point | C38: 1 | E38: 20 | F38: 0 | G38: =sum(I38:BU38)-(I38+P38+AE38+AO38+AP38+AS38+AU38+BB38+BS38) -> 0.21 | Y38: 0.05 | AV38: 0.05 | BM38: 0.1 | BR38: 0.01 | BS38: 0.15 | CP38: =1-0.36 -> 0.64 | CS38: =sum(I38:CQ38) -> 1
A39: 45360 | B39: Barber's point | C39: 1 | E39: 18 | F39: 0 | G39: =sum(I39:BU39)-(I39+P39+AE39+AO39+AP39+AS39+AU39+BB39+BS39) -> 0.12 | AU39: 0.1 | AV39: 0.02 | BM39: 0.1 | BS39: 0.15 | CP39: =1-0.37 -> 0.63 | CS39: =sum(I39:CQ39) -> 1
A40: 45360 | B40: Barber's point | C40: 1 | E40: 16 | F40: 0 | G40: =sum(I40:BU40)-(I40+P40+AE40+AO40+AP40+AS40+AU40+BB40+BS40) -> 0.32 | M40: 0.2 | BM40: 0.1 | BR40: 0.02 | BS40: =1-0.62 -> 0.38 | CP40: 0.3 | CS40: =sum(I40:CQ40) -> 1
...
